Workbook

Sheet 총괄표(경기도)
A1: □ 경기도 민간/분양 미 분양주택 현황 (총괄)-기재된 숫자는 분양되지 않은 주택 수를 의미함
A2: 시군별 | B2: 전월대비 미분양 증감현황 | C2: 민간 분양 주택('26. 09월 30일 기준) | H2: 민간 분양 주택('26. 08월 31일 기준)
C3: 계 | D3: 전용 40㎡이하 | E3: 전용 40-60㎡ | F3: 전용 60-85㎡ | G3: 전용 85㎡초과 | H3: 계 | I3: 전용 40㎡이하 | J3: 전용 40-60㎡ | K3: 전용 60-85㎡ | L3: 전용 85㎡초과
A4: 경기도 | B4: =C4-H4 -> -707 | C4: =SUM(C5:C35) -> 13802 | D4: =SUM(D5:D35) -> 327 | E4: =SUM(E5:E35) -> 542 | F4: =SUM(F5:F35) -> 10356 | G4: =SUM(G5:G35) -> 2577 | H4: =SUM(H5:H35) -> 14509 | I4: =SUM(I5:I35) -> 329 | J4: =SUM(J5:J35) -> 629 | ... L4: =SUM(L5:L35) -> 2747
A5: 수원시 | B5: =C5-H5 -> -22 | C5: =SUM(D5:G5) -> 21 | D5: 0 | E5: 0 | F5: 21 | G5: 0 | H5: =SUM(I5:L5) -> 43 | I5: 0 | J5: 0 | K5: 43 | L5: 0
A6: 용인시 | B6: =C6-H6 -> 98 | C6: =SUM(D6:G6) -> 790 | D6: 244 | E6: 73 | F6: 461 | G6: 12 | H6: =SUM(I6:L6) -> 692 | I6: 244 | J6: 96 | K6: 340 | L6: 12
A7: 고양시 | B7: =C7-H7 -> -1 | C7: =SUM(D7:G7) -> 53 | D7: 1 | E7: 0 | F7: 52 | G7: 0 | H7: =SUM(I7:L7) -> 54 | I7: 1 | J7: 0 | K7: 53 | L7: 0
A8: 성남시 | B8: =C8-H8 -> -5 | C8: =SUM(D8:G8) -> 19 | D8: 0 | E8: 19 | F8: 0 | G8: 0 | H8: =SUM(I8:L8) -> 24 | I8: 2 | J8: 21 | K8: 1 | L8: 0
A9: 화성시 | B9: =C9-H9 -> 0 | C9: =SUM(D9:G9) -> 57 | D9: 0 | E9: 41 | F9: 13 | G9: 3 | H9: =SUM(I9:L9) -> 57 | I9: 0 | J9: 41 | K9: 13 | L9: 3
A10: 부천시 | B10: =C10-H10 -> -19 | C10: =SUM(D10:G10) -> 60 | D10: 0 | E10: 32 | F10: 28 | G10: 0 | H10: =SUM(I10:L10) -> 79 | I10: 0 | J10: 40 | K10: 39 | L10: 0
A11: 남양주시 | B11: =C11-H11 -> -37 | C11: =SUM(D11:G11) -> 424 | D11: 0 | E11: 105 | F11: 49 | G11: 270 | H11: =SUM(I11:L11) -> 461 | I11: 0 | J11: 113 | K11: 69 | L11: 279
A12: 안산시 | B12: =C12-H12 -> 0 | C12: =SUM(D12:G12) -> 0 | D12: 0 | E12: 0 | F12: 0 | G12: 0 | H12: =SUM(I12:L12) -> 0 | I12: 0 | J12: 0 | K12: 0 | L12: 0
A13: 평택시 | B13: =C13-H13 -> -250 | C13: =SUM(D13:G13) -> 3358 | D13: 0 | E13: 27 | F13: 2173 | G13: 1158 | H13: =SUM(I13:L13) -> 3608 | I13: 0 | J13: 27 | K13: 2372 | L13: 1209
A14: 안양시 | B14: =C14-H14 -> 0 | C14: =SUM(D14:G14) -> 61 | D14: 0 | E14: 61 | F14: 0 | G14: 0 | H14: =SUM(I14:L14) -> 61 | I14: 0 | J14: 61 | K14: 0 | L14: 0
A15: 시흥시 | B15: =C15-H15 -> -41 | C15: =SUM(D15:G15) -> 359 | D15: 0 | E15: 3 | F15: 335 | G15: 21 | H15: =SUM(I15:L15) -> 400 | I15: 0 | J15: 3 | K15: 371 | L15: 26
A16: 김포시 | B16: =C16-H16 -> -22 | C16: =SUM(D16:G16) -> 765 | D16: 0 | E16: 0 | F16: 741 | G16: 24 | H16: =SUM(I16:L16) -> 787 | I16: 0 | J16: 0 | K16: 763 | L16: 24
... A35: 연천군 | B35: =C35-H35 -> -2 | C35: =SUM(D35:G35) -> 30 | D35: 0 | E35: 0 | F35: 0 | G35: 30 | H35: =SUM(I35:L35) -> 32 | I35: 0 | J35: 0 | K35: 0 | L35: 32
A37: □ 경기도 민간/분양 미분양주택 현황(준공후)
A39: 시군별 | B39: 전월대비 미분양 증감현황 | C39: 민간 분양 주택('26. 09월 30일 기준) | H39: 민간 분양 주택('26. 08월 31일 기준)
C40: 계 | D40: 전용 40㎡이하 | E40: 전용 40-60㎡ | F40: 전용 60-85㎡ | G40: 전용 85㎡초과 | H40: 계 | I40: 전용 40㎡이하 | J40: 전용 40-60㎡ | K40: 전용 60-85㎡ | L40: 전용 85㎡초과
A41: 경기도 | B41: =C41-H41 -> 83 | C41: =SUM(C42:C72) -> 2377 | D41: =SUM(D42:D72) -> 327 | E41: =SUM(E42:E72) -> 359 | F41: =SUM(F42:F72) -> 1424 | G41: =SUM(G42:G72) -> 267 | H41: =SUM(H42:H72) -> 2294 | I41: =SUM(I42:I72) -> 329 | J41: =SUM(J42:J72) -> 366 | ... L41: =SUM(L42:L72) -> 267
A42: 수원시 | B42: =C42-H42 -> -7 | C42: =SUM(D42:G42) -> 10 | D42: 0 | E42: 0 | F42: 10 | G42: 0 | H42: =SUM(I42:L42) -> 17 | I42: 0 | J42: 0 | K42: 17 | L42: 0
A43: 용인시 | B43: =C43-H43 -> -11 | C43: =SUM(D43:G43) -> 371 | D43: 244 | E43: 10 | F43: 105 | G43: 12 | H43: =SUM(I43:L43) -> 382 | I43: 244 | J43: 10 | K43: 116 | L43: 12
A44: 고양시 | B44: =C44-H44 -> -1 | C44: =SUM(D44:G44) -> 53 | D44: 1 | E44: 0 | F44: 52 | G44: 0 | H44: =SUM(I44:L44) -> 54 | I44: 1 | J44: 0 | K44: 53 | L44: 0
A45: 성남시 | B45: =C45-H45 -> -5 | C45: =SUM(D45:G45) -> 19 | D45: 0 | E45: 19 | F45: 0 | G45: 0 | H45: =SUM(I45:L45) -> 24 | I45: 2 | J45: 21 | K45: 1 | L45: 0
A46: 화성시 | B46: =C46-H46 -> 0 | C46: =SUM(D46:G46) -> 57 | D46: 0 | E46: 41 | F46: 13 | G46: 3 | H46: =SUM(I46:L46) -> 57 | I46: 0 | J46: 41 | K46: 13 | L46: 3
A47: 부천시 | B47: =C47-H47 -> -3 | C47: =SUM(D47:G47) -> 5 | D47: 0 | E47: 4 | F47: 1 | G47: 0 | H47: =SUM(I47:L47) -> 8 | I47: 0 | J47: 4 | K47: 4 | L47: 0
A48: 남양주시 | B48: =C48-H48 -> -9 | C48: =SUM(D48:G48) -> 311 | D48: 0 | E48: 105 | F48: 6 | G48: 200 | H48: =SUM(I48:L48) -> 320 | I48: 0 | J48: 113 | K48: 7 | L48: 200
A49: 안산시 | B49: =C49-H49 -> 0 | C49: =SUM(D49:G49) -> 0 | D49: 0 | E49: 0 | F49: 0 | G49: 0 | H49: =SUM(I49:L49) -> 0 | I49: 0 | J49: 0 | K49: 0 | L49: 0
A50: 평택시 | B50: =C50-H50 -> 18 | C50: =SUM(D50:G50) -> 79 | D50: 0 | E50: 0 | F50: 78 | G50: 1 | H50: =SUM(I50:L50) -> 61 | I50: 0 | J50: 0 | K50: 60 | L50: 1
A51: 안양시 | B51: =C51-H51 -> 0 | C51: =SUM(D51:G51) -> 61 | D51: 0 | E51: 61 | F51: 0 | G51: 0 | H51: =SUM(I51:L51) -> 61 | I51: 0 | J51: 61 | K51: 0 | L51: 0
A52: 시흥시 | B52: =C52-H52 -> 0 | C52: =SUM(D52:G52) -> 7 | D52: 0 | E52: 3 | F52: 4 | G52: 0 | H52: =SUM(I52:L52) -> 7 | I52: 0 | J52: 3 | K52: 4 | L52: 0
A53: 김포시 | B53: =C53-H53 -> -5 | C53: =SUM(D53:G53) -> 47 | D53: 0 | E53: 0 | F53: 45 | G53: 2 | H53: =SUM(I53:L53) -> 52 | I53: 0 | J53: 0 | K53: 50 | L53: 2
... A72: 연천군 | B72: =C72-H72 -> -2 | C72: =SUM(D72:G72) -> 30 | D72: 0 | E72: 0 | F72: 0 | G72: 30 | H72: =SUM(I72:L72) -> 32 | I72: 0 | J72: 0 | K72: 0 | L72: 32
I75: 담당부서 : 경기도 주택정책과 031-8008-4927

Sheet 업체별 현황 
A1: □ 경기도 민간부문 미분양 현황 ('26.09.30. 기준)-기재된 숫자는 분양되지 않은 주택 수를 의미함
A2: 지역 | D2: 소 재 지 | G2: 사업자 (전화번호) | J2: 유형 | L2: 분양내용 | M2: 미분양결과 | P2: 분양 승인일 | Q2: 계약 마감일 | R2: 입주예정 (준공)월 | S2: 준공여부 (준공/미준공) | T2: 지구명 (00지구) | U2: 택지종류 (민간/공공)
A4: 도 | B4: 시 | C4: 구(동,읍) | G4: 시공사 (전화번호) | H4: 시 행 사 | I4: 분양상담 | J4: (민간 /공공) | K4: (임대 /분양) | L4: 규모별 (전용 ㎡) | M4: 총분양 가구수 | N4: 전월 ('26.08/31) | O4: 당해월 ('26.09/30)
A6: 경기도 | D6: 합계 | M6: =M20+M53+M70+M136+M253+M280+M387+M484+M509+M518+M573+M630+M768+M774+M802+M872+M902+M918+M928+M938+M984+M991+M1050+M1079+M1103+M1112+M1117+M1137 -> 85420 | N6: =N20+N53+N70+N136+N253+N280+N387+N484+N509+N518+N573+N630+N768+N774+N802+N872+N902+N918+N928+N938+N984+N991+N1050+N1079+N1103+N1112+N1117+N1137 -> 14509 | O6: =O20+O53+O70+O136+O253+O280+O387+O484+O509+O518+O573+O630+O768+O774+O802+O872+O902+O918+O928+O938+O984+O991+O1050+O1079+O1103+O1112+O1117+O1137 -> 13802
A7: 경기도 | B7: 수원시 | C7: 장안구 | D7: 경기도 수원시 장안구 이목동 511-1번지 일원 | G7: 대방건설(주) (1577-7347) | H7: 디비이엔씨(주) (1577-7347) | I7: 북수원 이목지구 디에트르 더리체 분양사무소 (1688-4007) | J7: 민간 | K7: 분양 | L7: 84A | M7: 374 | N7: 0 | O7: 0 | P7: 2024-09 | Q7: 2024-10 | R7: 2027-08 | S7: 미준공 | T7: 이목지구 | U7: 공공
L8: 84B | M8: 394 | N8: 0 | O8: 0
G9: 소 계 | M9: =SUM(M7:M8) -> 768 | N9: =SUM(N7:N8) -> 0 | O9: =SUM(O7:O8) -> 0
C10: 권선구 | D10: 오목천동 315-2 외2 | G10: 에스지씨이앤씨 주식회사 (02-489-8414) | H10: 윈앤윈종합개발㈜ (031-895-6747) | I10: 윈앤윈종합개발㈜ (031-895-6747) | J10: 민간 | K10: 분양 | L10: 84A (84.9439) | M10: 39 | N10: 3 | O10: 1 | P10: 2023-08 | Q10: 2023-1 | R10: 2026-02 | S10: 준공 | T10: 해당없음 | U10: 민간
L11: 84B (84.2465) | M11: 39 | N11: 1 | O11: 1
L12: 84C (84.1954) | M12: 70 | N12: 10 | O12: 5
L13: 84D (84.9149) | M13: 18 | N13: 2 | O13: 2
L14: 84E (84.9119) | M14: 18 | N14: 1 | O14: 1
L15: 84F (84.9873) | M15: 17 | N15: 0 | O15: 0
G16: 소 계 | M16: =SUM(M10:M15) -> 201 | N16: =SUM(N10:N15) -> 17 | O16: =SUM(O10:O15) -> 10
C17: 권선구 | D17: 평동 135-1 일원 | G17: 동아건설산업㈜ (031-227-7207) | H17: 에스엠하이플러스㈜ (02-6940-9635) ㈜아주엠앤씨 (02-767-1502) | I17: 수원역 아너스빌 타임원 견본주택 (1544-6236) | J17: 민간 | K17: 분양 | L17: 84A (84.6388) | M17: 58 | N17: 13 | O17: 6 | P17: 2026. 5. 21. | Q17: (정당) 2026. 06. 24. (예당) 2026. 06. 27. | R17: 2028. 10. | S17: 미준공 | T17: 평동지구 | U17: 민간
L18: 84B (84.8874) | M18: 56 | N18: 13 | O18: 5
G19: 소 계 | M19: =SUM(M17:M18) -> 114 | N19: =SUM(N17:N18) -> 26 | O19: =SUM(O17:O18) -> 11
B20: 지 역 총 괄 | M20: =M9+M16+M19 -> 1083 | N20: =N9+N16+N19 -> 43 | O20: =O9+O16+O19 -> 21
B21: 고양시 | C21: - | D21: 단지요청에 의한 비공개 | G21: - | H21: - | I21: - | K21: 분양 | L21: 84.7888 | M21: 332 | N21: 0 | O21: 0 | P21: 2024-6 | Q21: 2024-7 | R21: 2028-7 | S21: 미준공 | T21: - | U21: -
L22: 84.665 | M22: 284 | N22: 0 | O22: 0
L23: 99.9552 | M23: 598 | N23: 0 | O23: 0
L24: 99.7505 | M24: 256 | N24: 0 | O24: 0
L25: 170.2121 | M25: 2 | N25: 0 | O25: 0
G26: 소 계 | M26: =SUM(M21:M25) -> 1472 | N26: =SUM(N21:N25) -> 0 | O26: =SUM(O21:O25) -> 0
C27: - | D27: 단지요청에 의한 비공개 | G27: - | H27: - | I27: - | K27: 분양 | L27: 59.7591 | M27: 0 | N27: 0 | O27: 0 | P27: 2024-12 | Q27: 2024-12 | R27: 2027-2 | S27: 미준공 | T27: - | U27: -
L28: 84.522 | M28: 112 | N28: 0 | O28: 0
L29: 84.4895 | M29: 0 | N29: 0 | O29: 0
G30: 소 계 | M30: =SUM(M27:M29) -> 112 | N30: =SUM(N27:N29) -> 0 | O30: =SUM(O27:O29) -> 0
C31: - | D31: 단지요청에 의한 비공개 | G31: - | H31: - | I31: - | K31: 분양 | L31: 59.7591 | M31: 31 | N31: 0 | O31: 0 | P31: 2024-12 | Q31: 2024-12 | R31: 2027-2 | S31: 미준공 | T31: - | U31: -
L32: 59.7591 | M32: 2 | N32: 0 | O32: 0
L33: 59.7591 | M33: 2 | N33: 0 | O33: 0
G34: 소 계 | M34: =SUM(M31:M33) -> 35 | N34: =SUM(N31:N33) -> 0 | O34: =SUM(O31:O33) -> 0
C35: 덕양구 | D35: 경기도 고양시 덕양구 오부자로15 | G35: 한림건설㈜ (055-289-9000) | H35: 한림건설㈜ (055-289-9000) | I35: 한림건설㈜ (055-289-9000) | J35: ㈜대송 (02-371-1752) | K35: 분양 | L35: 72.94 | M35: 214 | N35: 0 | O35: 0 | P35: - | Q35: 2017-09 | R35: 2020-01 | S35: 준공 | T35: 지축지구 | U35: 공공
L36: 72.95 | M36: 214 | N36: 0 | O36: 0
L37: 84.98 | M37: 337 | N37: 3 | O37: 3
L38: 84.97 | M38: 337 | N38: 1 | O38: 1
G39: 소 계 | M39: =SUM(M35:M38) -> 1102 | N39: =SUM(N35:N38) -> 4 | O39: =SUM(O35:O38) -> 4
C40: 덕양구 | D40: 경기도 고양시 덕양구 오금로 33 | G40: ㈜대송 | H40: ㈜생보부동산신탁 | I40: ㈜대송 (054-774-7500) | J40: 민간 | K40: 분양 | L40: 84.9647 | M40: 40 | N40: 17 | O40: 16 | P40: 2020-06 | Q40: 2020-06 | R40: 2022-11 | S40: 준공 | T40: 삼송지구 | U40: 공공
L41: 84.6287 | M41: 20 | N41: 16 | O41: 16
L42: 84.7357 | M42: 20 | N42: 16 | O42: 16
...

Sheet 총괄표(국토부통계누리순서)
A1: □ 경기도 민간/분양 미분양주택 현황 (총괄)
A2: 시군별 | B2: 전월대비 미분양 증감현황 | C2: 민간 분양 주택('24. 12월 31일 기준) | H2: 민간 분양 주택('24. 11월 30일 기준)
C3: 계 | D3: 전용 40㎡이하 | E3: 전용 40-60㎡ | F3: 전용 60-85㎡ | G3: 전용 85㎡초과 | H3: 계 | I3: 전용 40㎡이하 | J3: 전용 40-60㎡ | K3: 전용 60-85㎡ | L3: 전용 85㎡초과
A4: 경기도 | B4: =C4-H4 -> -707 | C4: =SUM(C5:C35) -> 13802 | D4: =SUM(D5:D35) -> 327 | E4: =SUM(E5:E35) -> 542 | F4: =SUM(F5:F35) -> 10356 | G4: =SUM(G5:G35) -> 2577 | H4: =SUM(H5:H35) -> 14509 | I4: =SUM(I5:I35) -> 329 | J4: =SUM(J5:J35) -> 629 | ... L4: =SUM(L5:L35) -> 2747
A5: 수원시 | B5: =C5-H5 -> -22 | C5: =SUM(D5:G5) -> 21 | D5: ='총괄표(경기도)'!D5 -> 0 | E5: ='총괄표(경기도)'!E5 -> 0 | F5: ='총괄표(경기도)'!F5 -> 21 | G5: ='총괄표(경기도)'!G5 -> 0 | H5: =SUM(I5:L5) -> 43 | I5: ='총괄표(경기도)'!I5 -> 0 | J5: ='총괄표(경기도)'!J5 -> 0 | K5: ='총괄표(경기도)'!K5 -> 43 | L5: ='총괄표(경기도)'!L5 -> 0
A6: 성남시 | B6: =C6-H6 -> -5 | C6: =SUM(D6:G6) -> 19 | D6: ='총괄표(경기도)'!D8 -> 0 | E6: ='총괄표(경기도)'!E8 -> 19 | F6: ='총괄표(경기도)'!F8 -> 0 | G6: ='총괄표(경기도)'!G8 -> 0 | H6: =SUM(I6:L6) -> 24 | I6: ='총괄표(경기도)'!I8 -> 2 | J6: ='총괄표(경기도)'!J8 -> 21 | K6: ='총괄표(경기도)'!K8 -> 1 | L6: ='총괄표(경기도)'!L8 -> 0
A7: 의정부시 | B7: =C7-H7 -> -17 | C7: =SUM(D7:G7) -> 783 | D7: ='총괄표(경기도)'!D18 -> 82 | E7: ='총괄표(경기도)'!E18 -> 36 | F7: ='총괄표(경기도)'!F18 -> 616 | G7: ='총괄표(경기도)'!G18 -> 49 | H7: =SUM(I7:L7) -> 800 | I7: ='총괄표(경기도)'!I18 -> 82 | J7: ='총괄표(경기도)'!J18 -> 36 | K7: ='총괄표(경기도)'!K18 -> 630 | L7: ='총괄표(경기도)'!L18 -> 52
A8: 안양시 | B8: =C8-H8 -> 0 | C8: =SUM(D8:G8) -> 61 | D8: ='총괄표(경기도)'!D14 -> 0 | E8: ='총괄표(경기도)'!E14 -> 61 | F8: ='총괄표(경기도)'!F14 -> 0 | G8: ='총괄표(경기도)'!G14 -> 0 | H8: =SUM(I8:L8) -> 61 | I8: ='총괄표(경기도)'!I14 -> 0 | J8: ='총괄표(경기도)'!J14 -> 61 | K8: ='총괄표(경기도)'!K14 -> 0 | L8: ='총괄표(경기도)'!L14 -> 0
A9: 부천시 | B9: =C9-H9 -> -19 | C9: =SUM(D9:G9) -> 60 | D9: ='총괄표(경기도)'!D10 -> 0 | E9: ='총괄표(경기도)'!E10 -> 32 | F9: ='총괄표(경기도)'!F10 -> 28 | G9: ='총괄표(경기도)'!G10 -> 0 | H9: =SUM(I9:L9) -> 79 | I9: ='총괄표(경기도)'!I10 -> 0 | J9: ='총괄표(경기도)'!J10 -> 40 | K9: ='총괄표(경기도)'!K10 -> 39 | L9: ='총괄표(경기도)'!L10 -> 0
A10: 광명시 | B10: =C10-H10 -> 0 | C10: =SUM(D10:G10) -> 2 | D10: ='총괄표(경기도)'!D20 -> 0 | E10: ='총괄표(경기도)'!E20 -> 1 | F10: ='총괄표(경기도)'!F20 -> 1 | G10: ='총괄표(경기도)'!G20 -> 0 | H10: =SUM(I10:L10) -> 2 | I10: ='총괄표(경기도)'!I20 -> 0 | J10: ='총괄표(경기도)'!J20 -> 1 | K10: ='총괄표(경기도)'!K20 -> 1 | L10: ='총괄표(경기도)'!L20 -> 0
A11: 평택시 | B11: =C11-H11 -> -250 | C11: =SUM(D11:G11) -> 3358 | D11: ='총괄표(경기도)'!D13 -> 0 | E11: ='총괄표(경기도)'!E13 -> 27 | F11: ='총괄표(경기도)'!F13 -> 2173 | G11: ='총괄표(경기도)'!G13 -> 1158 | H11: =SUM(I11:L11) -> 3608 | I11: ='총괄표(경기도)'!I13 -> 0 | J11: ='총괄표(경기도)'!J13 -> 27 | K11: ='총괄표(경기도)'!K13 -> 2372 | L11: ='총괄표(경기도)'!L13 -> 1209
A12: 동두천시 | B12: =C12-H12 -> 0 | C12: =SUM(D12:G12) -> 137 | D12: ='총괄표(경기도)'!D32 -> 0 | E12: ='총괄표(경기도)'!E32 -> 8 | F12: ='총괄표(경기도)'!F32 -> 129 | G12: ='총괄표(경기도)'!G32 -> 0 | H12: =SUM(I12:L12) -> 137 | I12: ='총괄표(경기도)'!I32 -> 0 | J12: ='총괄표(경기도)'!J32 -> 8 | K12: ='총괄표(경기도)'!K32 -> 129 | L12: ='총괄표(경기도)'!L32 -> 0
A13: 안산시 | B13: =C13-H13 -> 0 | C13: =SUM(D13:G13) -> 0 | D13: ='총괄표(경기도)'!D12 -> 0 | E13: ='총괄표(경기도)'!E12 -> 0 | F13: ='총괄표(경기도)'!F12 -> 0 | G13: ='총괄표(경기도)'!G12 -> 0 | H13: =SUM(I13:L13) -> 0 | I13: ='총괄표(경기도)'!I12 -> 0 | J13: ='총괄표(경기도)'!J12 -> 0 | K13: ='총괄표(경기도)'!K12 -> 0 | L13: ='총괄표(경기도)'!L12 -> 0
A14: 고양시 | B14: =C14-H14 -> -1 | C14: =SUM(D14:G14) -> 53 | D14: ='총괄표(경기도)'!D7 -> 1 | E14: ='총괄표(경기도)'!E7 -> 0 | F14: ='총괄표(경기도)'!F7 -> 52 | G14: ='총괄표(경기도)'!G7 -> 0 | H14: =SUM(I14:L14) -> 54 | I14: ='총괄표(경기도)'!I7 -> 1 | J14: ='총괄표(경기도)'!J7 -> 0 | K14: ='총괄표(경기도)'!K7 -> 53 | L14: ='총괄표(경기도)'!L7 -> 0
A15: 과천시 | B15: =C15-H15 -> 0 | C15: =SUM(D15:G15) -> 0 | D15: ='총괄표(경기도)'!D33 -> 0 | E15: ='총괄표(경기도)'!E33 -> 0 | F15: ='총괄표(경기도)'!F33 -> 0 | G15: ='총괄표(경기도)'!G33 -> 0 | H15: =SUM(I15:L15) -> 0 | I15: ='총괄표(경기도)'!I33 -> 0 | J15: ='총괄표(경기도)'!J33 -> 0 | K15: ='총괄표(경기도)'!K33 -> 0 | L15: ='총괄표(경기도)'!L33 -> 0
A16: 구리시 | B16: =C16-H16 -> -12 | C16: =SUM(D16:G16) -> 0 | D16: ='총괄표(경기도)'!D26 -> 0 | E16: ='총괄표(경기도)'!E26 -> 0 | F16: ='총괄표(경기도)'!F26 -> 0 | G16: ='총괄표(경기도)'!G26 -> 0 | H16: =SUM(I16:L16) -> 12 | I16: ='총괄표(경기도)'!I26 -> 0 | J16: ='총괄표(경기도)'!J26 -> 0 | K16: ='총괄표(경기도)'!K26 -> 12 | L16: ='총괄표(경기도)'!L26 -> 0
A17: 남양주시 | B17: =C17-H17 -> -37 | C17: =SUM(D17:G17) -> 424 | D17: ='총괄표(경기도)'!D11 -> 0 | E17: ='총괄표(경기도)'!E11 -> 105 | F17: ='총괄표(경기도)'!F11 -> 49 | G17: ='총괄표(경기도)'!G11 -> 270 | H17: =SUM(I17:L17) -> 461 | I17: ='총괄표(경기도)'!I11 -> 0 | J17: ='총괄표(경기도)'!J11 -> 113 | K17: ='총괄표(경기도)'!K11 -> 69 | L17: ='총괄표(경기도)'!L11 -> 279
A18: 오산시 | B18: =C18-H18 -> -578 | C18: =SUM(D18:G18) -> 1268 | D18: ='총괄표(경기도)'!D23 -> 0 | E18: ='총괄표(경기도)'!E23 -> 0 | F18: ='총괄표(경기도)'!F23 -> 1056 | G18: ='총괄표(경기도)'!G23 -> 212 | H18: =SUM(I18:L18) -> 1846 | I18: ='총괄표(경기도)'!I23 -> 0 | J18: ='총괄표(경기도)'!J23 -> 0 | K18: ='총괄표(경기도)'!K23 -> 1564 | L18: ='총괄표(경기도)'!L23 -> 282
A19: 시흥시 | B19: =C19-H19 -> -41 | C19: =SUM(D19:G19) -> 359 | D19: ='총괄표(경기도)'!D15 -> 0 | E19: ='총괄표(경기도)'!E15 -> 3 | F19: ='총괄표(경기도)'!F15 -> 335 | G19: ='총괄표(경기도)'!G15 -> 21 | H19: =SUM(I19:L19) -> 400 | I19: ='총괄표(경기도)'!I15 -> 0 | J19: ='총괄표(경기도)'!J15 -> 3 | K19: ='총괄표(경기도)'!K15 -> 371 | L19: ='총괄표(경기도)'!L15 -> 26
A20: 군포시 | B20: =C20-H20 -> 0 | C20: =SUM(D20:G20) -> 0 | D20: ='총괄표(경기도)'!D22 -> 0 | E20: ='총괄표(경기도)'!E22 -> 0 | F20: ='총괄표(경기도)'!F22 -> 0 | G20: ='총괄표(경기도)'!G22 -> 0 | H20: =SUM(I20:L20) -> 0 | I20: ='총괄표(경기도)'!I22 -> 0 | J20: ='총괄표(경기도)'!J22 -> 0 | K20: ='총괄표(경기도)'!K22 -> 0 | L20: ='총괄표(경기도)'!L22 -> 0
A21: 의왕시 | B21: =C21-H21 -> 0 | C21: =SUM(D21:G21) -> 0 | D21: ='총괄표(경기도)'!D28 -> 0 | E21: ='총괄표(경기도)'!E28 -> 0 | F21: ='총괄표(경기도)'!F28 -> 0 | G21: ='총괄표(경기도)'!G28 -> 0 | H21: =SUM(I21:L21) -> 0 | I21: ='총괄표(경기도)'!I28 -> 0 | J21: ='총괄표(경기도)'!J28 -> 0 | K21: ='총괄표(경기도)'!K28 -> 0 | L21: ='총괄표(경기도)'!L28 -> 0
A22: 하남시 | B22: =C22-H22 -> 0 | C22: =SUM(D22:G22) -> 3 | D22: ='총괄표(경기도)'!D21 -> 0 | E22: ='총괄표(경기도)'!E21 -> 0 | F22: ='총괄표(경기도)'!F21 -> 0 | G22: ='총괄표(경기도)'!G21 -> 3 | H22: =SUM(I22:L22) -> 3 | I22: ='총괄표(경기도)'!I21 -> 0 | J22: ='총괄표(경기도)'!J21 -> 0 | K22: ='총괄표(경기도)'!K21 -> 0 | L22: ='총괄표(경기도)'!L21 -> 3
A23: 용인시 | B23: =C23-H23 -> 98 | C23: =SUM(D23:G23) -> 790 | D23: ='총괄표(경기도)'!D6 -> 244 | E23: ='총괄표(경기도)'!E6 -> 73 | F23: ='총괄표(경기도)'!F6 -> 461 | G23: ='총괄표(경기도)'!G6 -> 12 | H23: =SUM(I23:L23) -> 692 | I23: ='총괄표(경기도)'!I6 -> 244 | J23: ='총괄표(경기도)'!J6 -> 96 | K23: ='총괄표(경기도)'!K6 -> 340 | L23: ='총괄표(경기도)'!L6 -> 12
A24: 파주시 | B24: =C24-H24 -> 0 | C24: =SUM(D24:G24) -> 1 | D24: ='총괄표(경기도)'!D17 -> 0 | E24: ='총괄표(경기도)'!E17 -> 0 | F24: ='총괄표(경기도)'!F17 -> 0 | G24: ='총괄표(경기도)'!G17 -> 1 | H24: =SUM(I24:L24) -> 1 | I24: ='총괄표(경기도)'!I17 -> 0 | J24: ='총괄표(경기도)'!J17 -> 0 | K24: ='총괄표(경기도)'!K17 -> 0 | L24: ='총괄표(경기도)'!L17 -> 1
A25: 이천시 | B25: =C25-H25 -> 447 | C25: =SUM(D25:G25) -> 1475 | D25: ='총괄표(경기도)'!D25 -> 0 | E25: ='총괄표(경기도)'!E25 -> 10 | F25: ='총괄표(경기도)'!F25 -> 1362 | G25: ='총괄표(경기도)'!G25 -> 103 | H25: =SUM(I25:L25) -> 1028 | I25: ='총괄표(경기도)'!I25 -> 0 | J25: ='총괄표(경기도)'!J25 -> 16 | K25: ='총괄표(경기도)'!K25 -> 906 | L25: ='총괄표(경기도)'!L25 -> 106
A26: 안성시 | B26: =C26-H26 -> -80 | C26: =SUM(D26:G26) -> 839 | D26: ='총괄표(경기도)'!D27 -> 0 | E26: ='총괄표(경기도)'!E27 -> 0 | F26: ='총괄표(경기도)'!F27 -> 829 | G26: ='총괄표(경기도)'!G27 -> 10 | H26: =SUM(I26:L26) -> 919 | I26: ='총괄표(경기도)'!I27 -> 0 | J26: ='총괄표(경기도)'!J27 -> 0 | K26: ='총괄표(경기도)'!K27 -> 909 | L26: ='총괄표(경기도)'!L27 -> 10
A27: 김포시 | B27: =C27-H27 -> -22 | C27: =SUM(D27:G27) -> 765 | D27: ='총괄표(경기도)'!D16 -> 0 | E27: ='총괄표(경기도)'!E16 -> 0 | F27: ='총괄표(경기도)'!F16 -> 741 | G27: ='총괄표(경기도)'!G16 -> 24 | H27: =SUM(I27:L27) -> 787 | I27: ='총괄표(경기도)'!I16 -> 0 | J27: ='총괄표(경기도)'!J16 -> 0 | K27: ='총괄표(경기도)'!K16 -> 763 | L27: ='총괄표(경기도)'!L16 -> 24
A28: 양주시 | B28: =C28-H28 -> -130 | C28: =SUM(D28:G28) -> 1807 | D28: ='총괄표(경기도)'!D24 -> 0 | E28: ='총괄표(경기도)'!E24 -> 6 | F28: ='총괄표(경기도)'!F24 -> 1416 | G28: ='총괄표(경기도)'!G24 -> 385 | H28: =SUM(I28:L28) -> 1937 | I28: ='총괄표(경기도)'!I24 -> 0 | J28: ='총괄표(경기도)'!J24 -> 44 | K28: ='총괄표(경기도)'!K24 -> 1483 | L28: ='총괄표(경기도)'!L24 -> 410
A29: 여주시 | B29: =C29-H29 -> -17 | C29: =SUM(D29:G29) -> 154 | D29: ='총괄표(경기도)'!D31 -> 0 | E29: ='총괄표(경기도)'!E31 -> 0 | F29: ='총괄표(경기도)'!F31 -> 144 | G29: ='총괄표(경기도)'!G31 -> 10 | H29: =SUM(I29:L29) -> 171 | I29: ='총괄표(경기도)'!I31 -> 0 | J29: ='총괄표(경기도)'!J31 -> 0 | K29: ='총괄표(경기도)'!K31 -> 161 | L29: ='총괄표(경기도)'!L31 -> 10
A30: 화성시 | B30: =C30-H30 -> 0 | C30: =SUM(D30:G30) -> 57 | D30: ='총괄표(경기도)'!D9 -> 0 | E30: ='총괄표(경기도)'!E9 -> 41 | F30: ='총괄표(경기도)'!F9 -> 13 | G30: ='총괄표(경기도)'!G9 -> 3 | H30: =SUM(I30:L30) -> 57 | I30: ='총괄표(경기도)'!I9 -> 0 | J30: ='총괄표(경기도)'!J9 -> 41 | K30: ='총괄표(경기도)'!K9 -> 13 | L30: ='총괄표(경기도)'!L9 -> 3
A31: 광주시 | B31: =C31-H31 -> -7 | C31: =SUM(D31:G31) -> 51 | D31: ='총괄표(경기도)'!D19 -> 0 | E31: ='총괄표(경기도)'!E19 -> 4 | F31: ='총괄표(경기도)'!F19 -> 33 | G31: ='총괄표(경기도)'!G19 -> 14 | H31: =SUM(I31:L31) -> 58 | I31: ='총괄표(경기도)'!I19 -> 0 | J31: ='총괄표(경기도)'!J19 -> 7 | K31: ='총괄표(경기도)'!K19 -> 37 | L31: ='총괄표(경기도)'!L19 -> 14
A32: 연천군 | B32: =C32-H32 -> -2 | C32: =SUM(D32:G32) -> 30 | D32: ='총괄표(경기도)'!D35 -> 0 | E32: ='총괄표(경기도)'!E35 -> 0 | F32: ='총괄표(경기도)'!F35 -> 0 | G32: ='총괄표(경기도)'!G35 -> 30 | H32: =SUM(I32:L32) -> 32 | I32: ='총괄표(경기도)'!I35 -> 0 | J32: ='총괄표(경기도)'!J35 -> 0 | K32: ='총괄표(경기도)'!K35 -> 0 | L32: ='총괄표(경기도)'!L35 -> 32
A33: 포천시 | B33: =C33-H33 -> 0 | C33: =SUM(D33:G33) -> 123 | D33: ='총괄표(경기도)'!D29 -> 0 | E33: ='총괄표(경기도)'!E29 -> 68 | F33: ='총괄표(경기도)'!F29 -> 55 | G33: ='총괄표(경기도)'!G29 -> 0 | H33: =SUM(I33:L33) -> 123 | I33: ='총괄표(경기도)'!I29 -> 0 | J33: ='총괄표(경기도)'!J29 -> 68 | K33: ='총괄표(경기도)'!K29 -> 55 | L33: ='총괄표(경기도)'!L29 -> 0
A34: 가평군 | B34: =C34-H34 -> -5 | C34: =SUM(D34:G34) -> 870 | D34: ='총괄표(경기도)'!D34 -> 0 | E34: ='총괄표(경기도)'!E34 -> 35 | F34: ='총괄표(경기도)'!F34 -> 567 | G34: ='총괄표(경기도)'!G34 -> 268 | H34: =SUM(I34:L34) -> 875 | I34: ='총괄표(경기도)'!I34 -> 0 | J34: ='총괄표(경기도)'!J34 -> 35 | K34: ='총괄표(경기도)'!K34 -> 570 | L34: ='총괄표(경기도)'!L34 -> 270
A35: 양평군 | B35: =C35-H35 -> -7 | C35: =SUM(D35:G35) -> 292 | D35: ='총괄표(경기도)'!D30 -> 0 | E35: ='총괄표(경기도)'!E30 -> 13 | F35: ='총괄표(경기도)'!F30 -> 275 | G35: ='총괄표(경기도)'!G30 -> 4 | H35: =SUM(I35:L35) -> 299 | I35: ='총괄표(경기도)'!I30 -> 0 | J35: ='총괄표(경기도)'!J30 -> 12 | K35: ='총괄표(경기도)'!K30 -> 283 | L35: ='총괄표(경기도)'!L30 -> 4
A38: □ 경기도 민간/분양 미분양주택 현황(준공후)
A39: 시군별 | B39: 전월대비 미분양 증감현황 | C39: 민간 분양 주택('24. 12월 31일 기준) | H39: 민간 분양 주택('24. 11월 30일 기준)
C40: 계 | D40: 전용 40㎡이하 | E40: 전용 40-60㎡ | F40: 전용 60-85㎡ | G40: 전용 85㎡초과 | H40: 계 | I40: 전용 40㎡이하 | J40: 전용 40-60㎡ | K40: 전용 60-85㎡ | L40: 전용 85㎡초과
A41: 경기도 | B41: =C41-H41 -> 83 | C41: =SUM(C42:C72) -> 2377 | D41: =SUM(D42:D72) -> 327 | E41: =SUM(E42:E72) -> 359 | F41: =SUM(F42:F72) -> 1424 | G41: =SUM(G42:G72) -> 267 | H41: =SUM(H42:H72) -> 2294 | I41: =SUM(I42:I72) -> 329 | J41: =SUM(J42:J72) -> 366 | ... L41: =SUM(L42:L72) -> 267
A42: 수원시 | B42: =C42-H42 -> -7 | C42: =SUM(D42:G42) -> 10 | D42: ='총괄표(경기도)'!D42 -> 0 | E42: ='총괄표(경기도)'!E42 -> 0 | F42: ='총괄표(경기도)'!F42 -> 10 | G42: ='총괄표(경기도)'!G42 -> 0 | H42: =SUM(I42:L42) -> 17 | I42: ='총괄표(경기도)'!I42 -> 0 | J42: ='총괄표(경기도)'!J42 -> 0 | K42: ='총괄표(경기도)'!K42 -> 17 | L42: ='총괄표(경기도)'!L42 -> 0
...
